<?xml version="1.0"?>
<!-- j2n6s200 refers to jaco v2 6DOF non-spherical 2fingers -->


<robot xmlns:xi="http://www.w3.org/2001/XInclude"
	xmlns:gazebo="http://playerstage.sourceforge.net/gazebo/xmlschema/#gz"
    xmlns:model="http://playerstage.sourceforge.net/gazebo/xmlschema/#model"
	xmlns:sensor="http://playerstage.sourceforge.net/gazebo/xmlschema/#sensor"
	xmlns:body="http://playerstage.sourceforge.net/gazebo/xmlschema/#body"
    xmlns:geom="http://playerstage.sourceforge.net/gazebo/xmlschema/#geom"
    xmlns:joint="http://playerstage.sourceforge.net/gazebo/xmlschema/#joint"
	xmlns:controller="http://playerstage.sourceforge.net/gazebo/xmlschema/#controller"
	xmlns:interface="http://playerstage.sourceforge.net/gazebo/xmlschema/#interface"
	xmlns:rendering="http://playerstage.sourceforge.net/gazebo/xmlschema/#rendering"
    xmlns:renderable="http://playerstage.sourceforge.net/gazebo/xmlschema/#renderable"
    xmlns:physics="http://playerstage.sourceforge.net/gazebo/xmlschema/#physics"
	xmlns:xacro="http://www.ros.org/wiki/xacro" name="j2n6s200">


  <xacro:include filename="$(find kinova_description)/urdf/j2n6s200.xacro"/>

  <link name="root"/>

  <!-- for gazebo -->
  <link name="world"/>
  
  <joint name="connect_root_and_world" type="fixed">
    <child link="root" />
    <parent link="world" />
    <origin xyz="0 0 0" rpy="0 0 0" />    
  </joint> 

  <xacro:property name="robot_root" value="root" />

          <link name="ee1_link">
            <visual>
                <origin xyz="0.0 0.0 0.0" rpy="0.0 0.0 1.5"/>
                <geometry>
                    <cylinder radius="0.2" length="0.5"/>
                </geometry>
            </visual>
            <collision>
                <geometry>
                    <cylinder radius="0.2" length="0.5"/>
                </geometry>
            </collision>
        </link>
        <joint name="ee1_joint" type="revolute">
            <parent link="${prefix}_link_6"/>
            <child link="ee1_link"/>
            <axis xyz="0 0 1"/>  
            <limit effort="0" lower="-3.14" upper="3.14" velocity="0.6283185307179586"/>
            <origin rpy="0 0 0" xyz="0 0 0"/>

        </joint>

  <xacro:j2n6s200  base_parent="${robot_root}"/>

</robot>
